Workbook
Name economist_emea_tier2: 'Master_Plan_2025_Bigquery CB do'!$D$67:$AY$88
Name economist_latam: 'Master_Plan_2025_Bigquery CB do'!$D$90:$AY$111
Name wsj_non_media: 'Master_Plan_2025_Bigquery CB do'!$D$251:$AY$259
Name economist_us: 'Master_Plan_2025_Bigquery CB do'!$D$5:$AY$23
Name nativo_nam: 'Master_Plan_2025_Bigquery CB do'!$D$261:$AY$299
Name wsj_global: 'Master_Plan_2025_Bigquery CB do'!$D$225:$AY$245
Name mobkoi_global: 'Master_Plan_2025_Bigquery CB do'!$D$382:$AY$418
Name economist_apac: 'Master_Plan_2025_Bigquery CB do'!$D$113:$AY$128
Name economist_added_value: 'Master_Plan_2025_Bigquery CB do'!$D$130:$AY$137
Name ft_apac: 'Master_Plan_2025_Bigquery CB do'!$D$191:$AY$200
Name ft_emea_tier1: 'Master_Plan_2025_Bigquery CB do'!$D$151:$AY$160
Name wsj_nam: 'Master_Plan_2025_Bigquery CB do'!$D$210:$AY$223
Name ft_emea_tier2: 'Master_Plan_2025_Bigquery CB do'!$D$164:$AY$175
Name economist_ca: 'Master_Plan_2025_Bigquery CB do'!$D$26:$AY$45
Name ft_added_value: 'Master_Plan_2025_Bigquery CB do'!$D$202:$AY$207
Name ft_latam: 'Master_Plan_2025_Bigquery CB do'!$D$180:$AY$189
Name mobkoi_nam: 'Master_Plan_2025_Bigquery CB do'!$D$342:$AY$376
Name nativo_global: 'Master_Plan_2025_Bigquery CB do'!$D$303:$AY$339
Name ft_us: 'Master_Plan_2025_Bigquery CB do'!$D$140:$AY$149
Name economist_emea_tier1: 'Master_Plan_2025_Bigquery CB do'!$D$47:$AY$65

Sheet Master Plan 2025
I4: Total Year | P4: SPEND | AB4: IMPRESSONS | AN4: CLICKS
B5: VENDOR | C5: REGION | D5: TARGETING | E5: TARGETING TYPE | F5: PLACEMENT | G5: PLACEMENT NAME | H5: PLACEMENT GROUP NAME | I5: SPEND (NET) | J5: IMPRESSIONS | K5: CPM / FLAT RATE (NET) | L5: CLICKS | M5: CTR | N5: VIEWABILITY | O5: Monthly Unique users | P5: FEBRUARY | Q5: MARCH | R5: APRIL | S5: MAY | T5: JUNE | U5: JULY | V5: AUGUST | W5: SEPTEMBER | X5: OCTOBER | Y5: NOVEMBER | Z5: DECEMBER | AA5: JANUARY | AB5: FEBRUARY | AC5: MARCH | AD5: APRIL | AE5: MAY | AF5: JUNE | AG5: JULY | AH5: AUGUST | AI5: SEPTEMBER | AJ5: OCTOBER | AK5: NOVEMBER | AL5: DECEMBER | AM5: JANUARY | AN5: FEBRUARY | AO5: MARCH | AP5: APRIL | AQ5: MAY | AR5: JUNE | AS5: JULY | AT5: AUGUST | AU5: SEPTEMBER | AV5: OCTOBER | AW5: NOVEMBER | AX5: DECEMBER | AY5: JANUARY
B6: THE ECONOMIST | C6: ='Economist OLD'!B6 -> North America 0 US (US Metro targetting, Canada Country targetting) | D6: ='Economist OLD'!F7 -> C0Level + Custom audience targeting companies 5,000+ | E6: Audience | F6: ResponsiveBillboard | G6: Economist_US_Audience_Display_ResponsiveBillboard | H6: Economist_US_Audience | I6: =sum(P6:AA6) -> 5799.38 | J6: =sum(AB6:AM6) -> 116744.1 | K6: ='Economist OLD'!Q7 -> 49.676 | L6: ='Economist OLD'!AW7 -> 81.720871 | M6: ='Economist OLD'!AV7 -> 0.0007 | N6: 0.75 | O6: ='Economist OLD'!AS7 -> 581400 | P6: 0 | Q6: ='Economist OLD'!V7 -> 662.01481 | R6: ='Economist OLD'!V7 -> 662.01481 | S6: ='Economist OLD'!W7 -> 662.01481 | T6: ='Economist OLD'!X7 -> 662.01481 | U6: ='Economist OLD'!Y7 -> 662.01481 | V6: ='Economist OLD'!Z7 -> 857.78411 | W6: ='Economist OLD'!AA7 -> 195.76929 | X6: ='Economist OLD'!AB7 -> 662.01481 | Y6: ='Economist OLD'!AC7 -> 526.7767 | ... AA6: ='Economist OLD'!AE7 -> 93.004102 | AB6: 0 | AC6: ='Economist OLD'!AG7 -> 13326.653 | AD6: ='Economist OLD'!AH7 -> 13326.653 | AE6: ='Economist OLD'!AI7 -> 13326.653 | AF6: ='Economist OLD'!AJ7 -> 13326.653 | AG6: ='Economist OLD'!AK7 -> 13326.653 | AH6: ='Economist OLD'!AL7 -> 17267.576 | AI6: ='Economist OLD'!AM7 -> 3940.9231 | AJ6: ='Economist OLD'!AN7 -> 13326.653 | ... AM6: ='Economist OLD'!AQ7 -> 1872.214 | AN6: 0 | AO6: =$L$6/11 -> 7.4291701 | AP6: =$L$6/11 -> 7.4291701 | AQ6: =$L$6/11 -> 7.4291701 | AR6: =$L$6/11 -> 7.4291701 | AS6: =$L$6/11 -> 7.4291701 | AT6: =$L$6/11 -> 7.4291701 | AU6: =$L$6/11 -> 7.4291701 | AV6: =$L$6/11 -> 7.4291701 | ... AY6: =$L$6/11 -> 7.4291701
D7: ='Economist OLD'!F8 -> C0Level + Custom audience targeting companies 5,000+ | E7: Audience | F7: ='Economist OLD'!I8 -> 300x600 | G7: Economist_US_Audience_Display_300x600 | H7: Economist_US_Audience | I7: ='Economist OLD'!S8+P7 -> 5682.4985 | J7: ='Economist OLD'!M8 -> 85263.085 | K7: ='Economist OLD'!Q8 -> 41.92 | L7: ='Economist OLD'!AW8 -> 42.631543 | M7: ='Economist OLD'!AV8 -> 0.0005 | N7: 0.75 | O7: ='Economist OLD'!AS8 -> 581400 | P7: 2108.27 | Q7: ='Economist OLD'!V8 -> 408.00779 | R7: =Q7 -> 408.00779 | S7: ='Economist OLD'!W8 -> 408.00779 | T7: ='Economist OLD'!X8 -> 408.00779 | U7: ='Economist OLD'!Y8 -> 408.00779 | V7: ='Economist OLD'!Z8 -> 528.66279 | W7: ='Economist OLD'!AA8 -> 120.655 | X7: ='Economist OLD'!AB8 -> 408.00779 | Y7: ='Economist OLD'!AC8 -> 324.6589 | Z7: ='Economist OLD'!AD8 -> 94.885533 | AA7: ='Economist OLD'!AE8 -> 57.319561 | AB7: 50293 | AC7: ='Economist OLD'!AG8 -> 9733.0103 | AD7: ='Economist OLD'!AH8 -> 9733.0103 | AE7: ='Economist OLD'!AI8 -> 9733.0103 | AF7: ='Economist OLD'!AJ8 -> 9733.0103 | AG7: ='Economist OLD'!AK8 -> 9733.0103 | AH7: ='Economist OLD'!AL8 -> 12611.231 | AI7: ='Economist OLD'!AM8 -> 2878.2204 | AJ7: ='Economist OLD'!AN8 -> 9733.0103 | ... AM7: ='Economist OLD'!AQ8 -> 1367.3559 | AN7: 25 | AO7: =L7/11 -> 3.8755948 | AP7: =AO7 -> 3.8755948 | AQ7: =AP7 -> 3.8755948 | AR7: =AQ7 -> 3.8755948 | AS7: =AR7 -> 3.8755948 | AT7: =AS7 -> 3.8755948 | AU7: =AT7 -> 3.8755948 | AV7: =AU7 -> 3.8755948 | AW7: =AV7 -> 3.8755948 | ... AY7: =AX7 -> 3.8755948
D8: ='Economist OLD'!F9 -> C0Level + Custom audience targeting companies 5,000+ | E8: Audience | F8: ='Economist OLD'!I9 -> Interscroller | G8: Economist_US_Audience_Display_Interscroller | H8: Economist_US_Audience | I8: ='Economist OLD'!S9+P8 -> 5518.124 | J8: ='Economist OLD'!M9 -> 93833.589 | K8: ='Economist OLD'!Q9 -> 41.92 | L8: ='Economist OLD'!AW9 -> 281.50077 | M8: ='Economist OLD'!AV9 -> 0.003 | N8: 0.75 | O8: ='Economist OLD'!AS9 -> 581400 | P8: 1584.62 | Q8: ='Economist OLD'!V9 -> 449.02006 | R8: =Q8 -> 449.02006 | S8: ='Economist OLD'!W9 -> 449.02006 | T8: ='Economist OLD'!X9 -> 449.02006 | U8: ='Economist OLD'!Y9 -> 449.02006 | V8: ='Economist OLD'!Z9 -> 581.8031 | W8: ='Economist OLD'!AA9 -> 132.78304 | X8: ='Economist OLD'!AB9 -> 449.02006 | Y8: ='Economist OLD'!AC9 -> 357.29307 | Z8: ='Economist OLD'!AD9 -> 104.42327 | AA8: ='Economist OLD'!AE9 -> 63.081228 | AB8: 37801 | AC8: ='Economist OLD'!AG9 -> 10711.356 | AD8: ='Economist OLD'!AH9 -> 10711.356 | AE8: ='Economist OLD'!AI9 -> 10711.356 | AF8: ='Economist OLD'!AJ9 -> 10711.356 | AG8: ='Economist OLD'!AK9 -> 10711.356 | AH8: ='Economist OLD'!AL9 -> 13878.891 | AI8: ='Economist OLD'!AM9 -> 3167.5344 | AJ8: ='Economist OLD'!AN9 -> 10711.356 | ... AM8: ='Economist OLD'!AQ9 -> 1504.8003 | AN8: 113 | AO8: =L8/11 -> 25.590979 | AP8: =AO8 -> 25.590979 | AQ8: =AP8 -> 25.590979 | AR8: =AQ8 -> 25.590979 | AS8: =AR8 -> 25.590979 | AT8: =AS8 -> 25.590979 | AU8: =AT8 -> 25.590979 | AV8: =AU8 -> 25.590979 | AW8: =AV8 -> 25.590979 | ... AY8: =AX8 -> 25.590979
D9: ='Economist OLD'!F10 -> C0Level + ESG articles and content | E9: Audience+Contextual | F9: ResponsiveBillboard | G9: Economist_US_Audience+Contextual_Display_ResponsiveBillboard | H9: Economist_US_Audience+Contextual | I9: ='Economist OLD'!S10+P9 -> 3656.25 | J9: ='Economist OLD'!M10 -> 82440.812 | K9: ='Economist OLD'!Q10 -> 44.35 | L9: ='Economist OLD'!AW10 -> 57.708568 | M9: ='Economist OLD'!AV10 -> 0.0007 | N9: 0.75 | O9: ='Economist OLD'!AS10 -> 4175000 | P9: 0 | Q9: ='Economist OLD'!V10 -> 417.37076 | R9: =Q9 -> 417.37076 | S9: ='Economist OLD'!W10 -> 417.37076 | T9: ='Economist OLD'!X10 -> 417.37076 | U9: ='Economist OLD'!Y10 -> 417.37076 | V9: ='Economist OLD'!Z10 -> 540.79456 | W9: ='Economist OLD'!AA10 -> 123.42379 | X9: ='Economist OLD'!AB10 -> 417.37076 | Y9: ='Economist OLD'!AC10 -> 332.10918 | Z9: ='Economist OLD'!AD10 -> 97.062968 | AA9: ='Economist OLD'!AE10 -> 58.634931 | AB9: 0 | AC9: ='Economist OLD'!AG10 -> 9410.8402 | AD9: ='Economist OLD'!AH10 -> 9410.8402 | AE9: ='Economist OLD'!AI10 -> 9410.8402 | AF9: ='Economist OLD'!AJ10 -> 9410.8402 | AG9: ='Economist OLD'!AK10 -> 9410.8402 | AH9: ='Economist OLD'!AL10 -> 12193.789 | AI9: ='Economist OLD'!AM10 -> 2782.9491 | AJ9: ='Economist OLD'!AN10 -> 9410.8402 | ... AM9: ='Economist OLD'!AQ10 -> 1322.0954 | AN9: 0 | AO9: =L9/11 -> 5.2462335 | AP9: =AO9 -> 5.2462335 | AQ9: =AP9 -> 5.2462335 | AR9: =AQ9 -> 5.2462335 | AS9: =AR9 -> 5.2462335 | AT9: =AS9 -> 5.2462335 | AU9: =AT9 -> 5.2462335 | AV9: =AU9 -> 5.2462335 | AW9: =AV9 -> 5.2462335 | ... AY9: =AX9 -> 5.2462335
D10: ='Economist OLD'!F11 -> C0Level + ESG articles and content | E10: Audience+Contextual | F10: ='Economist OLD'!I11 -> 300x600 | G10: Economist_US_Audience+Contextual_Display_300x600 | H10: Economist_US_Audience+Contextual | I10: ='Economist OLD'!S11+P10 -> 2549.999 | J10: ='Economist OLD'!M11 -> 47754.062 | K10: ='Economist OLD'!Q11 -> 37.9 | L10: ='Economist OLD'!AW11 -> 23.877031 | M10: ='Economist OLD'!AV11 -> 0.0005 | N10: 0.75 | O10: ='Economist OLD'!AS11 -> 4175000 | P10: 740.12 | Q10: ='Economist OLD'!V11 -> 206.60255 | R10: =Q10 -> 206.60255 | S10: ='Economist OLD'!W11 -> 206.60255 | T10: ='Economist OLD'!X11 -> 206.60255 | U10: ='Economist OLD'!Y11 -> 206.60255 | V10: ='Economist OLD'!Z11 -> 267.69851 | W10: ='Economist OLD'!AA11 -> 61.095966 | X10: ='Economist OLD'!AB11 -> 206.60255 | Y10: ='Economist OLD'!AC11 -> 164.39724 | Z10: ='Economist OLD'!AD11 -> 48.047104 | AA10: ='Economist OLD'!AE11 -> 29.024856 | AB10: 19528 | AC10: ='Economist OLD'!AG11 -> 5451.2545 | AD10: ='Economist OLD'!AH11 -> 5451.2545 | AE10: ='Economist OLD'!AI11 -> 5451.2545 | AF10: ='Economist OLD'!AJ11 -> 5451.2545 | AG10: ='Economist OLD'!AK11 -> 5451.2545 | AH10: ='Economist OLD'!AL11 -> 7063.2853 | AI10: ='Economist OLD'!AM11 -> 1612.0308 | AJ10: ='Economist OLD'!AN11 -> 5451.2545 | ... AM10: ='Economist OLD'!AQ11 -> 765.82732 | AN10: 10 | AO10: =L10/11 -> 2.1706392 | AP10: =AO10 -> 2.1706392 | AQ10: =AP10 -> 2.1706392 | AR10: =AQ10 -> 2.1706392 | AS10: =AR10 -> 2.1706392 | AT10: =AS10 -> 2.1706392 | AU10: =AT10 -> 2.1706392 | AV10: =AU10 -> 2.1706392 | AW10: =AV10 -> 2.1706392 | ... AY10: =AX10 -> 2.1706392
D11: ='Economist OLD'!F12 -> C0Level + ESG articles and content | E11: Audience+Contextual | F11: ='Economist OLD'!I12 -> Interscroller | G11: Economist_US_Audience+Contextual_Display_Interscroller | H11: Economist_US_Audience+Contextual | I11: ='Economist OLD'!S12+P11 -> 3656.2558 | J11: ='Economist OLD'!M12 -> 82417.567 | K11: ='Economist OLD'!Q12 -> 37.9 | L11: ='Economist OLD'!AW12 -> 247.2527 | M11: ='Economist OLD'!AV12 -> 0.003 | N11: 0.75 | O11: ='Economist OLD'!AS12 -> 4175000 | P11: 532.63 | Q11: ='Economist OLD'!V12 -> 356.57028 | R11: =Q11 -> 356.57028 | S11: ='Economist OLD'!W12 -> 356.57028 | T11: ='Economist OLD'!X12 -> 356.57028 | U11: ='Economist OLD'!Y12 -> 356.57028 | V11: ='Economist OLD'!Z12 -> 462.01431 | W11: ='Economist OLD'!AA12 -> 105.44403 | X11: ='Economist OLD'!AB12 -> 356.57028 | Y11: ='Economist OLD'!AC12 -> 283.72917 | Z11: ='Economist OLD'!AD12 -> 82.923321 | AA11: ='Economist OLD'!AE12 -> 50.093288 | AB11: 14054 | AC11: ='Economist OLD'!AG12 -> 9408.1868 | AD11: ='Economist OLD'!AH12 -> 9408.1868 | AE11: ='Economist OLD'!AI12 -> 9408.1868 | AF11: ='Economist OLD'!AJ12 -> 9408.1868 | AG11: ='Economist OLD'!AK12 -> 9408.1868 | AH11: ='Economist OLD'!AL12 -> 12190.351 | AI11: ='Economist OLD'!AM12 -> 2782.1645 | AJ11: ='Economist OLD'!AN12 -> 9408.1868 | ... AM11: ='Economist OLD'!AQ12 -> 1321.7226 | AN11: 42 | AO11: =L11/11 -> 22.477518 | AP11: =AO11 -> 22.477518 | AQ11: =AP11 -> 22.477518 | AR11: =AQ11 -> 22.477518 | AS11: =AR11 -> 22.477518 | AT11: =AS11 -> 22.477518 | AU11: =AT11 -> 22.477518 | AV11: =AU11 -> 22.477518 | AW11: =AV11 -> 22.477518 | ... AY11: =AX11 -> 22.477518
D12: ='Economist OLD'!F13 -> Economist Subscribers | E12: Subscribers | F12: ResponsiveBillboard | G12: Economist_US_Subscribers_Display_ResponsiveBillboard | H12: Economist_US_Audience+Contextual | I12: ='Economist OLD'!S13+P12 -> 12799.372 | J12: ='Economist OLD'!M13 -> 257657.06 | K12: ='Economist OLD'!Q13 -> 49.676 | L12: ='Economist OLD'!AW13 -> 180.35994 | M12: ='Economist OLD'!AV13 -> 0.0007 | N12: 0.75 | O12: ='Economist OLD'!AS13 -> 456000 | P12: 0 | Q12: ='Economist OLD'!V13 -> 1461.0827 | R12: =Q12 -> 1461.0827 | S12: ='Economist OLD'!W13 -> 1461.0827 | T12: ='Economist OLD'!X13 -> 1461.0827 | U12: ='Economist OLD'!Y13 -> 1461.0827 | V12: ='Economist OLD'!Z13 -> 1893.1503 | W12: ='Economist OLD'!AA13 -> 432.06758 | X12: ='Economist OLD'!AB13 -> 1461.0827 | Y12: ='Economist OLD'!AC13 -> 1162.6089 | Z12: ='Economist OLD'!AD13 -> 339.78668 | AA12: ='Economist OLD'!AE13 -> 205.26231 | AB12: 0 | AC12: ='Economist OLD'!AG13 -> 29412.246 | AD12: ='Economist OLD'!AH13 -> 29412.246 | AE12: ='Economist OLD'!AI13 -> 29412.246 | AF12: ='Economist OLD'!AJ13 -> 29412.246 | AG12: ='Economist OLD'!AK13 -> 29412.246 | AH12: ='Economist OLD'!AL13 -> 38109.959 | AI12: ='Economist OLD'!AM13 -> 8697.7127 | AJ12: ='Economist OLD'!AN13 -> 29412.246 | ... AM12: ='Economist OLD'!AQ13 -> 4132.0216 | AN12: 0 | AO12: =L12/11 -> 16.396358 | AP12: =AO12 -> 16.396358 | AQ12: =AP12 -> 16.396358 | AR12: =AQ12 -> 16.396358 | AS12: =AR12 -> 16.396358 | AT12: =AS12 -> 16.396358 | AU12: =AT12 -> 16.396358 | AV12: =AU12 -> 16.396358 | AW12: =AV12 -> 16.396358 | ... AY12: =AX12 -> 16.396358
D13: ='Economist OLD'!F14 -> Economist Subscribers | E13: Subscribers | F13: ='Economist OLD'!I14 -> 300x600 | G13: Economist_US_Subscribers_Display_300x600 | H13: Economist_US_Subscribers | I13: ='Economist OLD'!S14+P13 -> 13222.503 | J13: ='Economist OLD'!M14 -> 263773.94 | K13: ='Economist OLD'!Q14 -> 41.92 | L13: ='Economist OLD'!AW14 -> 131.88697 | M13: ='Economist OLD'!AV14 -> 0.0005 | N13: 0.75 | O13: ='Economist OLD'!AS14 -> 456000 | P13: 2165.1 | Q13: ='Economist OLD'!V14 -> 1262.2323 | R13: =Q13 -> 1262.2323 | S13: ='Economist OLD'!W14 -> 1262.2323 | T13: ='Economist OLD'!X14 -> 1262.2323 | U13: ='Economist OLD'!Y14 -> 1262.2323 | V13: ='Economist OLD'!Z14 -> 1635.4964 | W13: ='Economist OLD'!AA14 -> 373.26405 | X13: ='Economist OLD'!AB14 -> 1262.2323 | Y13: ='Economist OLD'!AC14 -> 1004.3802 | Z13: ='Economist OLD'!AD14 -> 293.5424 | AA13: ='Economist OLD'!AE14 -> 177.32652 | AB13: 51648 | AC13: ='Economist OLD'!AG14 -> 30110.504 | AD13: ='Economist OLD'!AH14 -> 30110.504 | AE13: ='Economist OLD'!AI14 -> 30110.504 | AF13: ='Economist OLD'!AJ14 -> 30110.504 | AG13: ='Economist OLD'!AK14 -> 30110.504 | AH13: ='Economist OLD'!AL14 -> 39014.704 | AI13: ='Economist OLD'!AM14 -> 8904.1997 | AJ13: ='Economist OLD'!AN14 -> 30110.504 | ... AM13: ='Economist OLD'!AQ14 -> 4230.1174 | AN13: 26 | AO13: =L13/11 -> 11.989724 | AP13: =AO13 -> 11.989724 | AQ13: =AP13 -> 11.989724 | AR13: =AQ13 -> 11.989724 | AS13: =AR13 -> 11.989724 | AT13: =AS13 -> 11.989724 | AU13: =AT13 -> 11.989724 | AV13: =AU13 -> 11.989724 | AW13: =AV13 -> 11.989724 | ... AY13: =AX13 -> 11.989724
D14: ='Economist OLD'!F15 -> Economist Subscribers | E14: Subscribers | F14: ='Economist OLD'!I15 -> Interscroller | G14: Economist_US_Subscribers_Display_Interscroller | H14: Economist_US_Subscribers | I14: ='Economist OLD'!S15+P14 -> 12189.38 | J14: ='Economist OLD'!M15 -> 236439.64 | K14: ='Economist OLD'!Q15 -> 41.92 | L14: ='Economist OLD'!AW15 -> 709.31893 | M14: ='Economist OLD'!AV15 -> 0.003 | N14: 0.75 | O14: ='Economist OLD'!AS15 -> 456000 | P14: 2277.83 | Q14: ='Economist OLD'!V15 -> 1131.43 | R14: =Q14 -> 1131.43 | S14: ='Economist OLD'!W15 -> 1131.43 | T14: ='Economist OLD'!X15 -> 1131.43 | U14: ='Economist OLD'!Y15 -> 1131.43 | V14: ='Economist OLD'!Z15 -> 1466.0136 | W14: ='Economist OLD'!AA15 -> 334.58354 | X14: ='Economist OLD'!AB15 -> 1131.43 | Y14: ='Economist OLD'!AC15 -> 900.29856 | Z14: ='Economist OLD'!AD15 -> 263.12327 | AA14: ='Economist OLD'!AE15 -> 158.95058 | AB14: 54337 | AC14: ='Economist OLD'!AG15 -> 26990.22 | AD14: ='Economist OLD'!AH15 -> 26990.22 | AE14: ='Economist OLD'!AI15 -> 26990.22 | AF14: ='Economist OLD'!AJ15 -> 26990.22 | AG14: ='Economist OLD'!AK15 -> 26990.22 | AH14: ='Economist OLD'!AL15 -> 34971.698 | AI14: ='Economist OLD'!AM15 -> 7981.4776 | AJ14: ='Economist OLD'!AN15 -> 26990.22 | ... AM14: ='Economist OLD'!AQ15 -> 3791.7599 | AN14: 163 | AO14: =L14/11 -> 64.483539 | AP14: =AO14 -> 64.483539 | AQ14: =AP14 -> 64.483539 | AR14: =AQ14 -> 64.483539 | AS14: =AR14 -> 64.483539 | AT14: =AS14 -> 64.483539 | AU14: =AT14 -> 64.483539 | AV14: =AU14 -> 64.483539 | AW14: =AV14 -> 64.483539 | ... AY14: =AX14 -> 64.483539
D15: ='Economist OLD'!F16 -> Economist Subscribers | E15: Subscribers | F15: ='Economist OLD'!I16 -> 300x250 | G15: Economist_US_Subscribers_Display_300x250 | H15: Economist_US_Subscribers | I15: ='Economist OLD'!S16+P15 -> 11169.538 | J15: ='Economist OLD'!M16 -> 134448.47 | K15: ='Economist OLD'!Q16 -> 60 | L15: ='Economist OLD'!AW16 -> 94.113931 | M15: ='Economist OLD'!AV16 -> 0.0007 | N15: 0.75 | O15: ='Economist OLD'!AS16 -> 445000 | P15: 3102.63 | Q15: ='Economist OLD'!V16 -> 920.85927 | R15: =Q15 -> 920.85927 | S15: ='Economist OLD'!W16 -> 920.85927 | T15: ='Economist OLD'!X16 -> 920.85927 | U15: ='Economist OLD'!Y16 -> 920.85927 | V15: ='Economist OLD'!Z16 -> 1193.1734 | W15: ='Economist OLD'!AA16 -> 272.3141 | X15: ='Economist OLD'!AB16 -> 920.85927 | Y15: ='Economist OLD'!AC16 -> 732.74374 | Z15: ='Economist OLD'!AD16 -> 214.15332 | AA15: ='Economist OLD'!AE16 -> 129.36824 | AB15: 51711 | AC15: ='Economist OLD'!AG16 -> 15347.654 | AD15: ='Economist OLD'!AH16 -> 15347.654 | AE15: ='Economist OLD'!AI16 -> 15347.654 | AF15: ='Economist OLD'!AJ16 -> 15347.654 | AG15: ='Economist OLD'!AK16 -> 15347.654 | AH15: ='Economist OLD'!AL16 -> 19886.223 | AI15: ='Economist OLD'!AM16 -> 4538.5684 | AJ15: ='Economist OLD'!AN16 -> 15347.654 | ... AM15: ='Economist OLD'!AQ16 -> 2156.1373 | AN15: 36 | AO15: =L15/11 -> 8.5558119 | AP15: =AO15 -> 8.5558119 | AQ15: =AP15 -> 8.5558119 | AR15: =AQ15 -> 8.5558119 | AS15: =AR15 -> 8.5558119 | AT15: =AS15 -> 8.5558119 | AU15: =AT15 -> 8.5558119 | AV15: =AU15 -> 8.5558119 | AW15: =AV15 -> 8.5558119 | ... AY15: =AX15 -> 8.5558119
D16: ='Economist OLD'!F17 -> Economist Subscribers | E16: Subscribers | F16: ='Economist OLD'!I17 -> App Interscroller | G16: Economist_US_Subscribers_Display_appInterscroller | H16: Economist_US_Subscribers | I16: ='Economist OLD'!S17+P16 -> 57420 | J16: ='Economist OLD'!M17 -> 574200 | K16: ='Economist OLD'!Q17 -> 100 | L16: ='Economist OLD'!AW17 -> 0 | M16: ='Economist OLD'!AV17 -> 0 | N16: 0.75 | O16: ='Economist OLD'!AS17 -> 445000 | P16: 0 | Q16: ='Economist OLD'!V17 -> 5220 | R16: =Q16 -> 5220 | S16: ='Economist OLD'!W17 -> 5220 | T16: ='Economist OLD'!X17 -> 5220 | U16: ='Economist OLD'!Y17 -> 5220 | V16: ='Economist OLD'!Z17 -> 0 | W16: ='Economist OLD'!AA17 -> 10440 | X16: ='Economist OLD'!AB17 -> 5220 | Y16: ='Economist OLD'!AC17 -> 5220 | Z16: ='Economist OLD'!AD17 -> 5220 | AA16: ='Economist OLD'!AE17 -> 5220 | AB16: 0 | AC16: ='Economist OLD'!AG17 -> 52200 | AD16: ='Economist OLD'!AH17 -> 52200 | AE16: ='Economist OLD'!AI17 -> 52200 | AF16: ='Economist OLD'!AJ17 -> 52200 | AG16: ='Economist OLD'!AK17 -> 52200 | AH16: ='Economist OLD'!AL17 -> 0 | AI16: ='Economist OLD'!AM17 -> 104400 | AJ16: ='Economist OLD'!AN17 -> 52200 | ... AM16: ='Economist OLD'!AQ17 -> 52200 | AN16: 0 | AO16: 0 | AP16: 0 | AQ16: 0 | AR16: 0 | AS16: 0 | AT16: 0 | AU16: 0 | AV16: 0 | AW16: 0 | AX16: 0 | AY16: 0
D17: ='Economist OLD'!F18 -> Science & Technology (COP) | E17: Takeover | F17: Takeover | I17: ='Economist OLD'!S18+P17 -> 1486.1949 | J17: ='Economist OLD'!M18 -> 23490 | K17: ='Economist OLD'!Q18 -> 1486.1949 | L17: ='Economist OLD'!AW18 -> 16.443 | M17: ='Economist OLD'!AV18 -> 0.0007 | N17: 0.75 | O17: ='Economist OLD'!AS18 -> 445000 | P17: 0 | Q17: ='Economist OLD'!V18 -> 0 | R17: =Q17 -> 0 | S17: ='Economist OLD'!W18 -> 0 | T17: ='Economist OLD'!X18 -> 0 | U17: ='Economist OLD'!Y18 -> 0 | V17: ='Economist OLD'!Z18 -> 0 | W17: ='Economist OLD'!AA18 -> 1486.1949 | X17: ='Economist OLD'!AB18 -> 0 | Y17: ='Economist OLD'!AC18 -> 0 | Z17: ='Economist OLD'!AD18 -> 0 | AA17: ='Economist OLD'!AE18 -> 0 | AB17: 0 | AC17: ='Economist OLD'!AG18 -> 0 | AD17: ='Economist OLD'!AH18 -> 0 | AE17: ='Economist OLD'!AI18 -> 0 | AF17: ='Economist OLD'!AJ18 -> 0 | AG17: ='Economist OLD'!AK18 -> 0 | AH17: ='Economist OLD'!AL18 -> 0 | AI17: ='Economist OLD'!AM18 -> 23490 | AJ17: ='Economist OLD'!AN18 -> 0 | ... AM17: ='Economist OLD'!AQ18 -> 0 | AN17: 0 | AO17: =L17/11 -> 1.4948182 | AP17: =AO17 -> 1.4948182 | AQ17: =AP17 -> 1.4948182 | AR17: =AQ17 -> 1.4948182 | AS17: =AR17 -> 1.4948182 | AT17: =AS17 -> 1.4948182 | AU17: =AT17 -> 1.4948182 | AV17: =AU17 -> 1.4948182 | AW17: =AV17 -> 1.4948182 | ... AY17: =AX17 -> 1.4948182
D18: ='Economist OLD'!F19 -> Science & Technology (COP) | E18: Takeover | F18: Takeover | I18: ='Economist OLD'!S19+P18 -> 1486.1949 | J18: ='Economist OLD'!M19 -> 23490 | K18: ='Economist OLD'!Q19 -> 1486.1949 | L18: ='Economist OLD'!AW19 -> 16.443 | M18: ='Economist OLD'!AV19 -> 0.0007 | N18: 0.75 | O18: ='Economist OLD'!AS19 -> 445000 | P18: 0 | Q18: ='Economist OLD'!V19 -> 0 | R18: =Q18 -> 0 | S18: ='Economist OLD'!W19 -> 0 | T18: ='Economist OLD'!X19 -> 0 | U18: ='Economist OLD'!Y19 -> 0 | V18: ='Economist OLD'!Z19 -> 0 | W18: ='Economist OLD'!AA19 -> 1486.1949 | X18: ='Economist OLD'!AB19 -> 0 | Y18: ='Economist OLD'!AC19 -> 0 | Z18: ='Economist OLD'!AD19 -> 0 | AA18: ='Economist OLD'!AE19 -> 0 | AB18: 0 | AC18: ='Economist OLD'!AG19 -> 0 | AD18: ='Economist OLD'!AH19 -> 0 | AE18: ='Economist OLD'!AI19 -> 0 | AF18: ='Economist OLD'!AJ19 -> 0 | AG18: ='Economist OLD'!AK19 -> 0 | AH18: ='Economist OLD'!AL19 -> 0 | AI18: ='Economist OLD'!AM19 -> 23490 | AJ18: ='Economist OLD'!AN19 -> 0 | ... AM18: ='Economist OLD'!AQ19 -> 0 | AN18: 0 | AO18: =L18/11 -> 1.4948182 | AP18: =AO18 -> 1.4948182 | AQ18: =AP18 -> 1.4948182 | AR18: =AQ18 -> 1.4948182 | AS18: =AR18 -> 1.4948182 | AT18: =AS18 -> 1.4948182 | AU18: =AT18 -> 1.4948182 | AV18: =AU18 -> 1.4948182 | AW18: =AV18 -> 1.4948182 | ... AY18: =AX18 -> 1.4948182
D19: ='Economist OLD'!F20 -> Science & Technology (COP) | E19: Takeover | F19: Takeover | I19: ='Economist OLD'!S20+P19 -> 1486.1949 | J19: ='Economist OLD'!M20 -> 23490 | K19: ='Economist OLD'!Q20 -> 1486.1949 | L19: ='Economist OLD'!AW20 -> 16.443 | M19: ='Economist OLD'!AV20 -> 0.0007 | N19: 0.75 | O19: ='Economist OLD'!AS20 -> 445000 | P19: 0 | Q19: ='Economist OLD'!V20 -> 0 | R19: =Q19 -> 0 | S19: ='Economist OLD'!W20 -> 0 | T19: ='Economist OLD'!X20 -> 0 | U19: ='Economist OLD'!Y20 -> 0 | V19: ='Economist OLD'!Z20 -> 0 | W19: ='Economist OLD'!AA20 -> 0 | X19: ='Economist OLD'!AB20 -> 0 | Y19: ='Economist OLD'!AC20 -> 1486.1949 | Z19: ='Economist OLD'!AD20 -> 0 | AA19: ='Economist OLD'!AE20 -> 0 | AB19: 0 | AC19: ='Economist OLD'!AG20 -> 0 | AD19: ='Economist OLD'!AH20 -> 0 | AE19: ='Economist OLD'!AI20 -> 0 | AF19: ='Economist OLD'!AJ20 -> 0 | AG19: ='Economist OLD'!AK20 -> 0 | AH19: ='Economist OLD'!AL20 -> 0 | AI19: ='Economist OLD'!AM20 -> 0 | AJ19: ='Economist OLD'!AN20 -> 0 | ... AM19: ='Economist OLD'!AQ20 -> 0 | AN19: 0 | AO19: =L19/11 -> 1.4948182 | AP19: =AO19 -> 1.4948182 | AQ19: =AP19 -> 1.4948182 | AR19: =AQ19 -> 1.4948182 | AS19: =AR19 -> 1.4948182 | AT19: =AS19 -> 1.4948182 | AU19: =AT19 -> 1.4948182 | AV19: =AU19 -> 1.4948182 | AW19: =AV19 -> 1.4948182 | ... AY19: =AX19 -> 1.4948182
D20: ='Economist OLD'!F21 -> Business & Finance (Davos) | E20: Takeover | F20: Takeover | I20: ='Economist OLD'!S21+P20 -> 6253.125 | J20: ='Economist OLD'!M21 -> 100050 | K20: ='Economist OLD'!Q21 -> 6253.125 | L20: ='Economist OLD'!AW21 -> 70.035 | M20: ='Economist OLD'!AV21 -> 0.0007 | N20: 0.75 | O20: ='Economist OLD'!AS21 -> 445000 | P20: 0 | Q20: ='Economist OLD'!V21 -> 0 | R20: =Q20 -> 0 | S20: ='Economist OLD'!W21 -> 0 | T20: ='Economist OLD'!X21 -> 0 | U20: ='Economist OLD'!Y21 -> 0 | V20: ='Economist OLD'!Z21 -> 0 | W20: ='Economist OLD'!AA21 -> 0 | X20: ='Economist OLD'!AB21 -> 0 | Y20: ='Economist OLD'!AC21 -> 0 | Z20: ='Economist OLD'!AD21 -> 0 | AA20: ='Economist OLD'!AE21 -> 6253.125 | AB20: 0 | AC20: ='Economist OLD'!AG21 -> 0 | AD20: ='Economist OLD'!AH21 -> 0 | AE20: ='Economist OLD'!AI21 -> 0 | AF20: ='Economist OLD'!AJ21 -> 0 | AG20: ='Economist OLD'!AK21 -> 0 | AH20: ='Economist OLD'!AL21 -> 0 | AI20: ='Economist OLD'!AM21 -> 0 | AJ20: ='Economist OLD'!AN21 -> 0 | ... AM20: ='Economist OLD'!AQ21 -> 100050 | AN20: 0 | AO20: =L20/11 -> 6.3668182 | AP20: =AO20 -> 6.3668182 | AQ20: =AP20 -> 6.3668182 | AR20: =AQ20 -> 6.3668182 | AS20: =AR20 -> 6.3668182 | AT20: =AS20 -> 6.3668182 | AU20: =AT20 -> 6.3668182 | AV20: =AU20 -> 6.3668182 | AW20: =AV20 -> 6.3668182 | ... AY20: =AX20 -> 6.3668182
C21: TOTAL | I21: =SUM(I6:I20) -> 144375.01 | J21: =SUM(J6:J20) -> 2145492.3 | L21: =SUM(L6:L20) -> 1969.7352
C22: ='Economist OLD'!B22 -> North America 0 CA | D22: ='Economist OLD'!F23 -> C0Level + Custom audience targeting companies 5,000+ | E22: Audience | F22: ResponsiveBillboard | G22: Economist_CA_Audience_Display_ResponsiveBillboard | H22: Economist_CA_Audience | I22: ='Economist OLD'!S23+P22 -> 3599.7917 | J22: ='Economist OLD'!M23 -> 72465.409 | K22: ='Economist OLD'!Q23 -> 49.676 | L22: ='Economist OLD'!AW23 -> 50.725786 | M22: ='Economist OLD'!AV23 -> 0.0007 | N22: 0.75 | O22: ='Economist OLD'!AS23 -> 64600 | P22: 0 | Q22: ='Economist OLD'!U23 -> 359.90097 | R22: ='Economist OLD'!V23 -> 359.90097 | S22: ='Economist OLD'!W23 -> 359.90097 | T22: ='Economist OLD'!X23 -> 359.90097 | U22: ='Economist OLD'!Y23 -> 359.90097 | V22: ='Economist OLD'!Z23 -> 359.90097 | W22: ='Economist OLD'!AA23 -> 312.56137 | X22: ='Economist OLD'!AB23 -> 359.90097 | ... AA22: ='Economist OLD'!AE23 -> 260.31093 | AB22: 0 | AC22: ='Economist OLD'!AG23 -> 7244.9667 | AD22: ='Economist OLD'!AH23 -> 7244.9667 | AE22: ='Economist OLD'!AI23 -> 7244.9667 | AF22: ='Economist OLD'!AJ23 -> 7244.9667 | AG22: ='Economist OLD'!AK23 -> 7244.9667 | AH22: ='Economist OLD'!AL23 -> 7244.9667 | AI22: ='Economist OLD'!AM23 -> 6291.9996 | AJ22: ='Economist OLD'!AN23 -> 7244.9667 | ... AM22: ='Economist OLD'!AQ23 -> 5240.175 | AN22: 0 | AO22: =L22/11 -> 4.6114351 | AP22: =AO22 -> 4.6114351 | AQ22: =AP22 -> 4.6114351 | AR22: =AQ22 -> 4.6114351 | AS22: =AR22 -> 4.6114351 | AT22: =AS22 -> 4.6114351 | AU22: =AT22 -> 4.6114351 | AV22: =AU22 -> 4.6114351 | AW22: =AV22 -> 4.6114351 | ... AY22: =AX22 -> 4.6114351
D23: ='Economist OLD'!F24 -> C0Level + Custom audience targeting companies 5,000+ | E23: Audience | F23: ='Economist OLD'!I24 -> 300x600 | G23: Economist_CA_Audience_Display_300x600 | H23: Economist_CA_Audience | I23: ='Economist OLD'!S24+P23 -> 2560.8286 | J23: ='Economist OLD'!M24 -> 55336.083 | K23: ='Economist OLD'!Q24 -> 41.92 | L23: ='Economist OLD'!AW24 -> 27.668041 | M23: ='Economist OLD'!AV24 -> 0.0005 | N23: 0.75 | O23: ='Economist OLD'!AS24 -> 64600 | P23: 241.14 | Q23: ='Economist OLD'!U24 -> 231.91847 | R23: ='Economist OLD'!V24 -> 231.91847 | S23: ='Economist OLD'!W24 -> 231.91847 | T23: ='Economist OLD'!X24 -> 231.91847 | U23: ='Economist OLD'!Y24 -> 231.91847 | V23: ='Economist OLD'!Z24 -> 231.91847 | W23: ='Economist OLD'!AA24 -> 201.41306 | X23: ='Economist OLD'!AB24 -> 231.91847 | ... AA23: ='Economist OLD'!AE24 -> 167.74312 | AB23: 5752 | AC23: ='Economist OLD'!AG24 -> 5532.4062 | AD23: ='Economist OLD'!AH24 -> 5532.4062 | AE23: ='Economist OLD'!AI24 -> 5532.4062 | AF23: ='Economist OLD'!AJ24 -> 5532.4062 | AG23: ='Economist OLD'!AK24 -> 5532.4062 | AH23: ='Economist OLD'!AL24 -> 5532.4062 | AI23: ='Economist OLD'!AM24 -> 4804.7008 | AJ23: ='Economist OLD'!AN24 -> 5532.4062 | ... AM23: ='Economist OLD'!AQ24 -> 4001.5058 | AN23: 3 | AO23: =L23/11 -> 2.5152765 | AP23: =AO23 -> 2.5152765 | AQ23: =AP23 -> 2.5152765 | AR23: =AQ23 -> 2.5152765 | AS23: =AR23 -> 2.5152765 | AT23: =AS23 -> 2.5152765 | AU23: =AT23 -> 2.5152765 | AV23: =AU23 -> 2.5152765 | AW23: =AV23 -> 2.5152765 | ... AY23: =AX23 -> 2.5152765
D24: ='Economist OLD'!F25 -> C0Level + Custom audience targeting companies 5,000+ | E24: Audience | F24: ='Economist OLD'!I25 -> Interscroller | G24: Economist_CA_Audience_Display_Interscroller | H24: Economist_CA_Audience | I24: ='Economist OLD'!S25+P24 -> 3839.3743 | J24: ='Economist OLD'!M25 -> 88303.775 | K24: ='Economist OLD'!Q25 -> 41.92 | L24: ='Economist OLD'!AW25 -> 264.91133 | M24: ='Economist OLD'!AV25 -> 0.003 | N24: 0.75 | O24: ='Economist OLD'!AS25 -> 64600 | P24: 137.68 | Q24: ='Economist OLD'!U25 -> 370.08901 | R24: ='Economist OLD'!V25 -> 370.08901 | S24: ='Economist OLD'!W25 -> 370.08901 | T24: ='Economist OLD'!X25 -> 370.08901 | U24: ='Economist OLD'!Y25 -> 370.08901 | V24: ='Economist OLD'!Z25 -> 370.08901 | W24: ='Economist OLD'!AA25 -> 321.40933 | X24: ='Economist OLD'!AB25 -> 370.08901 | ... AA24: ='Economist OLD'!AE25 -> 267.67979 | AB24: 3284 | AC24: ='Economist OLD'!AG25 -> 8828.4593 | AD24: ='Economist OLD'!AH25 -> 8828.4593 | AE24: ='Economist OLD'!AI25 -> 8828.4593 | AF24: ='Economist OLD'!AJ25 -> 8828.4593 | AG24: ='Economist OLD'!AK25 -> 8828.4593 | AH24: ='Economist OLD'!AL25 -> 8828.4593 | AI24: ='Economist OLD'!AM25 -> 7667.2074 | AJ24: ='Economist OLD'!AN25 -> 8828.4593 | ... AM24: ='Economist OLD'!AQ25 -> 6385.4913 | AN24: 10 | AO24: =L24/11 -> 24.082848 | AP24: =AO24 -> 24.082848 | AQ24: =AP24 -> 24.082848 | AR24: =AQ24 -> 24.082848 | AS24: =AR24 -> 24.082848 | AT24: =AS24 -> 24.082848 | AU24: =AT24 -> 24.082848 | AV24: =AU24 -> 24.082848 | AW24: =AV24 -> 24.082848 | ... AY24: =AX24 -> 24.082848
D25: ='Economist OLD'!F26 -> C0Level + ESG articles and content | E25: Audience+Contextual | F25: ResponsiveBillboard | G25: Economist_CA_Audience+Contextual_Display_ResponsiveBillboard | H25: Economist_CA_Audience+Contextual | I25: ='Economist OLD'!S26+P25 -> 1885.4202 | J25: ='Economist OLD'!M26 -> 42512.292 | K25: ='Economist OLD'!Q26 -> 44.35 | L25: ='Economist OLD'!AW26 -> 29.758605 | M25: ='Economist OLD'!AV26 -> 0.0007 | N25: 0.75 | O25: ='Economist OLD'!AS26 -> 402000 | P25: 0 | Q25: ='Economist OLD'!U26 -> 188.50106 | R25: ='Economist OLD'!V26 -> 188.50106 | S25: ='Economist OLD'!W26 -> 188.50106 | T25: ='Economist OLD'!X26 -> 188.50106 | U25: ='Economist OLD'!Y26 -> 188.50106 | V25: ='Economist OLD'!Z26 -> 188.50106 | W25: ='Economist OLD'!AA26 -> 163.70656 | X25: ='Economist OLD'!AB26 -> 188.50106 | ... AA25: ='Economist OLD'!AE26 -> 136.33997 | AB25: 0 | AC25: ='Economist OLD'!AG26 -> 4250.3057 | AD25: ='Economist OLD'!AH26 -> 4250.3057 | AE25: ='Economist OLD'!AI26 -> 4250.3057 | AF25: ='Economist OLD'!AJ26 -> 4250.3057 | AG25: ='Economist OLD'!AK26 -> 4250.3057 | AH25: ='Economist OLD'!AL26 -> 4250.3057 | AI25: ='Economist OLD'!AM26 -> 3691.2415 | AJ25: ='Economist OLD'!AN26 -> 4250.3057 | ... AM25: ='Economist OLD'!AQ26 -> 3074.1819 | AN25: 0 | AO25: =M25/12 -> 5.8333333e-05 | AP25: =AO25 -> 5.8333333e-05 | AQ25: =AP25 -> 5.8333333e-05 | AR25: =AQ25 -> 5.8333333e-05 | AS25: =AR25 -> 5.8333333e-05 | AT25: =AS25 -> 5.8333333e-05 | AU25: =AT25 -> 5.8333333e-05 | AV25: =AU25 -> 5.8333333e-05 | AW25: =AV25 -> 5.8333333e-05 | ... AY25: =AX25 -> 5.8333333e-05
D26: ='Economist OLD'!F27 -> C0Level + ESG articles and content | E26: Audience+Contextual | F26: ='Economist OLD'!I27 -> 300x600 | G26: Economist_CA_Audience+Contextual_Display_300x600 | H26: Economist_CA_Audience+Contextual | I26: ='Economist OLD'!S27+P26 -> 850.00357 | J26: ='Economist OLD'!M27 -> 19523.841 | K26: ='Economist OLD'!Q27 -> 37.9 | L26: ='Economist OLD'!AW27 -> 9.7619205 | M26: ='Economist OLD'!AV27 -> 0.0005 | N26: 0.75 | O26: ='Economist OLD'!AS27 -> 402000 | P26: 110.05 | Q26: ='Economist OLD'!U27 -> 73.979283 | R26: ='Economist OLD'!V27 -> 73.979283 | S26: ='Economist OLD'!W27 -> 73.979283 | T26: ='Economist OLD'!X27 -> 73.979283 | U26: ='Economist OLD'!Y27 -> 73.979283 | V26: ='Economist OLD'!Z27 -> 73.979283 | W26: ='Economist OLD'!AA27 -> 64.248414 | X26: ='Economist OLD'!AB27 -> 73.979283 | ... AA26: ='Economist OLD'!AE27 -> 53.508098 | AB26: 2904 | AC26: ='Economist OLD'!AG27 -> 1951.96 | AD26: ='Economist OLD'!AH27 -> 1951.96 | AE26: ='Economist OLD'!AI27 -> 1951.96 | AF26: ='Economist OLD'!AJ27 -> 1951.96 | AG26: ='Economist OLD'!AK27 -> 1951.96 | AH26: ='Economist OLD'!AL27 -> 1951.96 | AI26: ='Economist OLD'!AM27 -> 1695.2088 | AJ26: ='Economist OLD'!AN27 -> 1951.96 | ... AM26: ='Economist OLD'!AQ27 -> 1411.8232 | AN26: 1 | AO26: =L26/11 -> 0.88744732 | AP26: =AO26 -> 0.88744732 | AQ26: =AP26 -> 0.88744732 | AR26: =AQ26 -> 0.88744732 | AS26: =AR26 -> 0.88744732 | AT26: =AS26 -> 0.88744732 | AU26: =AT26 -> 0.88744732 | AV26: =AU26 -> 0.88744732 | AW26: =AV26 -> 0.88744732 | ... AY26: =AX26 -> 0.88744732
D27: ='Economist OLD'!F28 -> C0Level + ESG articles and content | E27: Audience+Contextual | F27: ='Economist OLD'!I28 -> Interscroller | G27: Economist_CA_Audience+Contextual_Display_Interscroller | H27: Economist_CA_Audience+Contextual | I27: ='Economist OLD'!S28+P27 -> 1885.4168 | J27: ='Economist OLD'!M28 -> 45062.713 | K27: ='Economist OLD'!Q28 -> 37.9 | L27: ='Economist OLD'!AW28 -> 135.18814 | M27: ='Economist OLD'!AV28 -> 0.003 | N27: 0.75 | O27: ='Economist OLD'!AS28 -> 402000 | P27: 177.54 | Q27: ='Economist OLD'!U28 -> 170.75058 | R27: ='Economist OLD'!V28 -> 170.75058 | S27: ='Economist OLD'!W28 -> 170.75058 | T27: ='Economist OLD'!X28 -> 170.75058 | U27: ='Economist OLD'!Y28 -> 170.75058 | V27: ='Economist OLD'!Z28 -> 170.75058 | W27: ='Economist OLD'!AA28 -> 148.29089 | X27: ='Economist OLD'!AB28 -> 170.75058 | ... AA27: ='Economist OLD'!AE28 -> 123.50132 | AB27: 4685 | AC27: ='Economist OLD'!AG28 -> 4505.2923 | AD27: ='Economist OLD'!AH28 -> 4505.2923 | AE27: ='Economist OLD'!AI28 -> 4505.2923 | AF27: ='Economist OLD'!AJ28 -> 4505.2923 | AG27: ='Economist OLD'!AK28 -> 4505.2923 | AH27: ='Economist OLD'!AL28 -> 4505.2923 | AI27: ='Economist OLD'!AM28 -> 3912.6885 | AJ27: ='Economist OLD'!AN28 -> 4505.2923 | ... AM27: ='Economist OLD'!AQ28 -> 3258.6099 | AN27: 14 | AO27: =L27/11 -> 12.289831 | AP27: =AO27 -> 12.289831 | AQ27: =AP27 -> 12.289831 | AR27: =AQ27 -> 12.289831 | AS27: =AR27 -> 12.289831 | AT27: =AS27 -> 12.289831 | AU27: =AT27 -> 12.289831 | AV27: =AU27 -> 12.289831 | AW27: =AV27 -> 12.289831 | ... AY27: =AX27 -> 12.289831
D28: ='Economist OLD'!F29 -> Economist Subscribers | E28: Subscribers | F28: ResponsiveBillboard | G28: Economist_CA_Subscribers_Display_ResponsiveBillboard | H28: Economist_CA_Subscribers | I28: ='Economist OLD'!S29+P28 -> 5976.435 | J28: ='Economist OLD'!M29 -> 120308.3 | K28: ='Economist OLD'!Q29 -> 49.676 | L28: ='Economist OLD'!AW29 -> 84.215808 | M28: ='Economist OLD'!AV29 -> 0.0007 | N28: 0.75 | O28: ='Economist OLD'!AS29 -> 48000 | P28: 0 | Q28: ='Economist OLD'!U29 -> 597.51367 | R28: ='Economist OLD'!V29 -> 597.51367 | S28: ='Economist OLD'!W29 -> 597.51367 | T28: ='Economist OLD'!X29 -> 597.51367 | U28: ='Economist OLD'!Y29 -> 597.51367 | V28: ='Economist OLD'!Z29 -> 597.51367 | W28: ='Economist OLD'!AA29 -> 518.91967 | X28: ='Economist OLD'!AB29 -> 597.51367 | ... AA28: ='Economist OLD'!AE29 -> 432.17261 | AB28: 0 | AC28: ='Economist OLD'!AG29 -> 12028.216 | AD28: ='Economist OLD'!AH29 -> 12028.216 | AE28: ='Economist OLD'!AI29 -> 12028.216 | AF28: ='Economist OLD'!AJ29 -> 12028.216 | AG28: ='Economist OLD'!AK29 -> 12028.216 | AH28: ='Economist OLD'!AL29 -> 12028.216 | AI28: ='Economist OLD'!AM29 -> 10446.084 | AJ28: ='Economist OLD'!AN29 -> 12028.216 | ... AM28: ='Economist OLD'!AQ29 -> 8699.8271 | AN28: 0 | AO28: =L28/11 -> 7.6559825 | AP28: =AO28 -> 7.6559825 | AQ28: =AP28 -> 7.6559825 | AR28: =AQ28 -> 7.6559825 | AS28: =AR28 -> 7.6559825 | AT28: =AS28 -> 7.6559825 | AU28: =AT28 -> 7.6559825 | AV28: =AU28 -> 7.6559825 | AW28: =AV28 -> 7.6559825 | ... AY28: =AX28 -> 7.6559825
D29: ='Economist OLD'!F30 -> Economist Subscribers | E29: Subscribers | F29: ='Economist OLD'!I30 -> 300x600 | G29: Economist_CA_Subscribers_Display_300x600 | H29: Economist_CA_Subscribers | I29: ='Economist OLD'!S30+P29 -> 5894.1643 | J29: ='Economist OLD'!M30 -> 122593.85 | K29: ='Economist OLD'!Q30 -> 41.92 | L29: ='Economist OLD'!AW30 -> 61.296927 | M29: ='Economist OLD'!AV30 -> 0.0005 | N29: 0.75 | O29: ='Economist OLD'!AS30 -> 48000 | P29: 755.03 | Q29: ='Economist OLD'!U30 -> 513.80179 | R29: ='Economist OLD'!V30 -> 513.80179 | S29: ='Economist OLD'!W30 -> 513.80179 | T29: ='Economist OLD'!X30 -> 513.80179 | U29: ='Economist OLD'!Y30 -> 513.80179 | V29: ='Economist OLD'!Z30 -> 513.80179 | W29: ='Economist OLD'!AA30 -> 446.21885 | X29: ='Economist OLD'!AB30 -> 513.80179 | ... AA29: ='Economist OLD'!AE30 -> 371.62508 | AB29: 18011 | AC29: ='Economist OLD'!AG30 -> 12256.722 | AD29: ='Economist OLD'!AH30 -> 12256.722 | AE29: ='Economist OLD'!AI30 -> 12256.722 | AF29: ='Economist OLD'!AJ30 -> 12256.722 | AG29: ='Economist OLD'!AK30 -> 12256.722 | AH29: ='Economist OLD'!AL30 -> 12256.722 | AI29: ='Economist OLD'!AM30 -> 10644.534 | AJ29: ='Economist OLD'!AN30 -> 12256.722 | ... AM29: ='Economist OLD'!AQ30 -> 8865.102 | AN29: 9 | AO29: =M29/12 -> 4.1666667e-05 | AP29: =AO29 -> 4.1666667e-05 | AQ29: =AP29 -> 4.1666667e-05 | AR29: =AQ29 -> 4.1666667e-05 | AS29: =AR29 -> 4.1666667e-05 | AT29: =AS29 -> 4.1666667e-05 | AU29: =AT29 -> 4.1666667e-05 | AV29: =AU29 -> 4.1666667e-05 | AW29: =AV29 -> 4.1666667e-05 | ... AY29: =AX29 -> 4.1666667e-05
D30: ='Economist OLD'!F31 -> Economist Subscribers | E30: Subscribers | F30: ='Economist OLD'!I31 -> Interscroller | G30: Economist_CA_Subscribers_Display_Interscroller | H30: Economist_CA_Subscribers | I30: ='Economist OLD'!S31+P30 -> 6063.134 | J30: ='Economist OLD'!M31 -> 126523.23 | K30: ='Economist OLD'!Q31 -> 41.92 | L30: ='Economist OLD'!AW31 -> 379.5697 | M30: ='Economist OLD'!AV31 -> 0.003 | N30: 0.75 | O30: ='Economist OLD'!AS31 -> 48000 | P30: 759.28 | Q30: ='Economist OLD'!U31 -> 530.27018 | R30: ='Economist OLD'!V31 -> 530.27018 | S30: ='Economist OLD'!W31 -> 530.27018 | T30: ='Economist OLD'!X31 -> 530.27018 | U30: ='Economist OLD'!Y31 -> 530.27018 | V30: ='Economist OLD'!Z31 -> 530.27018 | W30: ='Economist OLD'!AA31 -> 460.52107 | X30: ='Economist OLD'!AB31 -> 530.27018 | ... AA30: ='Economist OLD'!AE31 -> 383.53641 | AB30: 18112 | AC30: ='Economist OLD'!AG31 -> 12649.575 | AD30: ='Economist OLD'!AH31 -> 12649.575 | AE30: ='Economist OLD'!AI31 -> 12649.575 | AF30: ='Economist OLD'!AJ31 -> 12649.575 | AG30: ='Economist OLD'!AK31 -> 12649.575 | AH30: ='Economist OLD'!AL31 -> 12649.575 | AI30: ='Economist OLD'!AM31 -> 10985.712 | AJ30: ='Economist OLD'!AN31 -> 12649.575 | ... AM30: ='Economist OLD'!AQ31 -> 9149.2465 | AN30: 54 | AO30: =L30/11 -> 34.506337 | AP30: =AO30 -> 34.506337 | AQ30: =AP30 -> 34.506337 | AR30: =AQ30 -> 34.506337 | AS30: =AR30 -> 34.506337 | AT30: =AS30 -> 34.506337 | AU30: =AT30 -> 34.506337 | AV30: =AU30 -> 34.506337 | AW30: =AV30 -> 34.506337 | ... AY30: =AX30 -> 34.506337
D31: ='Economist OLD'!F32 -> Economist Subscribers | E31: Subscribers | F31: ='Economist OLD'!I32 -> 300x250 | G31: Economist_CA_Subscribers_Display_300x250 | H31: Economist_CA_Subscribers | I31: ='Economist OLD'!S32+P31 -> 5389.8471 | J31: ='Economist OLD'!M32 -> 56669.451 | K31: ='Economist OLD'!Q32 -> 60 | L31: ='Economist OLD'!AW32 -> 39.668616 | M31: ='Economist OLD'!AV32 -> 0.0007 | N31: 0.75 | O31: ='Economist OLD'!AS32 -> 77000 | P31: 1989.68 | Q31: ='Economist OLD'!U32 -> 339.94285 | R31: ='Economist OLD'!V32 -> 339.94285 | S31: ='Economist OLD'!W32 -> 339.94285 | T31: ='Economist OLD'!X32 -> 339.94285 | U31: ='Economist OLD'!Y32 -> 339.94285 | V31: ='Economist OLD'!Z32 -> 339.94285 | W31: ='Economist OLD'!AA32 -> 295.22844 | X31: ='Economist OLD'!AB32 -> 339.94285 | ... AA31: ='Economist OLD'!AE32 -> 245.87553 | AB31: 33161 | AC31: ='Economist OLD'!AG32 -> 5665.7141 | AD31: ='Economist OLD'!AH32 -> 5665.7141 | AE31: ='Economist OLD'!AI32 -> 5665.7141 | AF31: ='Economist OLD'!AJ32 -> 5665.7141 | AG31: ='Economist OLD'!AK32 -> 5665.7141 | AH31: ='Economist OLD'!AL32 -> 5665.7141 | AI31: ='Economist OLD'!AM32 -> 4920.4741 | AJ31: ='Economist OLD'!AN32 -> 5665.7141 | ... AM31: ='Economist OLD'!AQ32 -> 4097.9254 | AN31: 23 | AO31: =L31/11 -> 3.6062378 | AP31: =AO31 -> 3.6062378 | AQ31: =AP31 -> 3.6062378 | AR31: =AQ31 -> 3.6062378 | AS31: =AR31 -> 3.6062378 | AT31: =AS31 -> 3.6062378 | AU31: =AT31 -> 3.6062378 | AV31: =AU31 -> 3.6062378 | AW31: =AV31 -> 3.6062378 | ... AY31: =AX31 -> 3.6062378
D32: ='Economist OLD'!F33 -> Economist Subscribers | E32: Subscribers | F32: ='Economist OLD'!I33 -> App Interscroller | G32: Economist_CA_Subscribers_Display_appInterscroller | H32: Economist_CA_Subscribers | I32: ='Economist OLD'!S33+P32 -> 8580 | J32: ='Economist OLD'!M33 -> 85800 | K32: ='Economist OLD'!Q33 -> 100 | L32: ='Economist OLD'!AW33 -> 0 | M32: ='Economist OLD'!AV33 -> 0 | N32: 0.75 | O32: ='Economist OLD'!AS33 -> 77000 | P32: 0 | Q32: ='Economist OLD'!U33 -> 780 | R32: ='Economist OLD'!V33 -> 780 | S32: ='Economist OLD'!W33 -> 780 | T32: ='Economist OLD'!X33 -> 780 | U32: ='Economist OLD'!Y33 -> 780 | V32: ='Economist OLD'!Z33 -> 0 | W32: ='Economist OLD'!AA33 -> 1560 | X32: ='Economist OLD'!AB33 -> 780 | ... AA32: ='Economist OLD'!AE33 -> 780 | AB32: 0 | AC32: ='Economist OLD'!AG33 -> 7800 | AD32: ='Economist OLD'!AH33 -> 7800 | AE32: ='Economist OLD'!AI33 -> 7800 | AF32: ='Economist OLD'!AJ33 -> 7800 | AG32: ='Economist OLD'!AK33 -> 7800 | AH32: ='Economist OLD'!AL33 -> 0 | AI32: ='Economist OLD'!AM33 -> 15600 | AJ32: ='Economist OLD'!AN33 -> 7800 | ... AM32: ='Economist OLD'!AQ33 -> 7800 | AN32: 0 | AO32: 0 | AP32: 0 | AQ32: 0 | AR32: 0 | AS32: 0 | AT32: 0 | AU32: 0 | AV32: 0 | AW32: 0 | AX32: 0 | AY32: 0
D33: ='Economist OLD'!F34 -> Science & Technology (COP) | E33: Takeover | F33: Takeover | I33: ='Economist OLD'!S34+P33 -> 222.0751 | J33: ='Economist OLD'!M34 -> 3510 | K33: ='Economist OLD'!Q34 -> 222.0751 | L33: ='Economist OLD'!AW34 -> 2.457 | M33: ='Economist OLD'!AV34 -> 0.0007 | N33: 0.75 | O33: ='Economist OLD'!AS34 -> 445000 | P33: 0 | Q33: ='Economist OLD'!U34 -> 0 | R33: ='Economist OLD'!V34 -> 0 | S33: ='Economist OLD'!W34 -> 0 | T33: ='Economist OLD'!X34 -> 0 | U33: ='Economist OLD'!Y34 -> 0 | V33: ='Economist OLD'!Z34 -> 0 | W33: ='Economist OLD'!AA34 -> 222.0751 | X33: ='Economist OLD'!AB34 -> 0 | ... AA33: ='Economist OLD'!AE34 -> 0 | AB33: 0 | AC33: ='Economist OLD'!AG34 -> 0 | AD33: ='Economist OLD'!AH34 -> 0 | AE33: ='Economist OLD'!AI34 -> 0 | AF33: ='Economist OLD'!AJ34 -> 0 | AG33: ='Economist OLD'!AK34 -> 0 | AH33: ='Economist OLD'!AL34 -> 0 | AI33: ='Economist OLD'!AM34 -> 3510 | AJ33: ='Economist OLD'!AN34 -> 0 | ... AM33: ='Economist OLD'!AQ34 -> 0 | AN33: 0 | AO33: =M33/12 -> 5.8333333e-05 | AP33: =AO33 -> 5.8333333e-05 | AQ33: =AP33 -> 5.8333333e-05 | AR33: =AQ33 -> 5.8333333e-05 | AS33: =AR33 -> 5.8333333e-05 | AT33: =AS33 -> 5.8333333e-05 | AU33: =AT33 -> 5.8333333e-05 | AV33: =AU33 -> 5.8333333e-05 | AW33: =AV33 -> 5.8333333e-05 | ... AY33: =AX33 -> 5.8333333e-05
D34: ='Economist OLD'!F35 -> Science & Technology (COP) | E34: Takeover | F34: Takeover | I34: ='Economist OLD'!S35+P34 -> 222.0751 | J34: ='Economist OLD'!M35 -> 3510 | K34: ='Economist OLD'!Q35 -> 222.0751 | L34: ='Economist OLD'!AW35 -> 2.457 | M34: ='Economist OLD'!AV35 -> 0.0007 | N34: 0.75 | O34: ='Economist OLD'!AS35 -> 445000 | P34: 0 | Q34: ='Economist OLD'!U35 -> 0 | R34: ='Economist OLD'!V35 -> 0 | S34: ='Economist OLD'!W35 -> 0 | T34: ='Economist OLD'!X35 -> 0 | U34: ='Economist OLD'!Y35 -> 0 | V34: ='Economist OLD'!Z35 -> 0 | W34: ='Economist OLD'!AA35 -> 222.0751 | X34: ='Economist OLD'!AB35 -> 0 | ... AA34: ='Economist OLD'!AE35 -> 0 | AB34: 0 | AC34: ='Economist OLD'!AG35 -> 0 | AD34: ='Economist OLD'!AH35 -> 0 | AE34: ='Economist OLD'!AI35 -> 0 | AF34: ='Economist OLD'!AJ35 -> 0 | AG34: ='Economist OLD'!AK35 -> 0 | AH34: ='Economist OLD'!AL35 -> 0 | AI34: ='Economist OLD'!AM35 -> 3510 | AJ34: ='Economist OLD'!AN35 -> 0 | ... AM34: ='Economist OLD'!AQ35 -> 0 | AN34: 0 | AO34: =L34/11 -> 0.22336364 | AP34: =AO34 -> 0.22336364 | AQ34: =AP34 -> 0.22336364 | AR34: =AQ34 -> 0.22336364 | AS34: =AR34 -> 0.22336364 | AT34: =AS34 -> 0.22336364 | AU34: =AT34 -> 0.22336364 | AV34: =AU34 -> 0.22336364 | AW34: =AV34 -> 0.22336364 | ... AY34: =AX34 -> 0.22336364
D35: ='Economist OLD'!F36 -> Science & Technology (COP) | E35: Takeover | F35: Takeover | I35: ='Economist OLD'!S36+P35 -> 222.0751 | J35: ='Economist OLD'!M36 -> 3510 | K35: ='Economist OLD'!Q36 -> 222.0751 | L35: ='Economist OLD'!AW36 -> 2.457 | M35: ='Economist OLD'!AV36 -> 0.0007 | N35: 0.75 | O35: ='Economist OLD'!AS36 -> 445000 | P35: 0 | Q35: ='Economist OLD'!U36 -> 0 | R35: ='Economist OLD'!V36 -> 0 | S35: ='Economist OLD'!W36 -> 0 | T35: ='Economist OLD'!X36 -> 0 | U35: ='Economist OLD'!Y36 -> 0 | V35: ='Economist OLD'!Z36 -> 0 | W35: ='Economist OLD'!AA36 -> 0 | X35: ='Economist OLD'!AB36 -> 0 | ... AA35: ='Economist OLD'!AE36 -> 0 | AB35: 0 | AC35: ='Economist OLD'!AG36 -> 0 | AD35: ='Economist OLD'!AH36 -> 0 | AE35: ='Economist OLD'!AI36 -> 0 | AF35: ='Economist OLD'!AJ36 -> 0 | AG35: ='Economist OLD'!AK36 -> 0 | AH35: ='Economist OLD'!AL36 -> 0 | AI35: ='Economist OLD'!AM36 -> 0 | AJ35: ='Economist OLD'!AN36 -> 0 | ... AM35: ='Economist OLD'!AQ36 -> 0 | AN35: 0 | AO35: =L35/11 -> 0.22336364 | AP35: =AO35 -> 0.22336364 | AQ35: =AP35 -> 0.22336364 | AR35: =AQ35 -> 0.22336364 | AS35: =AR35 -> 0.22336364 | AT35: =AS35 -> 0.22336364 | AU35: =AT35 -> 0.22336364 | AV35: =AU35 -> 0.22336364 | AW35: =AV35 -> 0.22336364 | ... AY35: =AX35 -> 0.22336364
D36: ='Economist OLD'!F37 -> Business & Finance (Davos) | E36: Takeover | F36: Takeover | I36: ='Economist OLD'!S37+P36 -> 934.375 | J36: ='Economist OLD'!M37 -> 14950 | K36: ='Economist OLD'!Q37 -> 934.375 | L36: ='Economist OLD'!AW37 -> 10.465 | M36: ='Economist OLD'!AV37 -> 0.0007 | N36: 0.75 | O36: ='Economist OLD'!AS37 -> 445000 | P36: 0 | Q36: ='Economist OLD'!U37 -> 0 | R36: ='Economist OLD'!V37 -> 0 | S36: ='Economist OLD'!W37 -> 0 | T36: ='Economist OLD'!X37 -> 0 | U36: ='Economist OLD'!Y37 -> 0 | V36: ='Economist OLD'!Z37 -> 0 | W36: ='Economist OLD'!AA37 -> 0 | X36: ='Economist OLD'!AB37 -> 0 | ... AA36: ='Economist OLD'!AE37 -> 934.375 | AB36: 0 | AC36: ='Economist OLD'!AG37 -> 0 | AD36: ='Economist OLD'!AH37 -> 0 | AE36: ='Economist OLD'!AI37 -> 0 | AF36: ='Economist OLD'!AJ37 -> 0 | AG36: ='Economist OLD'!AK37 -> 0 | AH36: ='Economist OLD'!AL37 -> 0 | AI36: ='Economist OLD'!AM37 -> 0 | AJ36: ='Economist OLD'!AN37 -> 0 | ... AM36: ='Economist OLD'!AQ37 -> 14950 | AN36: 0 | AO36: 0 | AP36: =AO36 -> 0 | AQ36: =AP36 -> 0 | AR36: =AQ36 -> 0 | AS36: =AR36 -> 0 | AT36: =AS36 -> 0 | AU36: =AT36 -> 0 | AV36: =AU36 -> 0 | AW36: =AV36 -> 0 | AX36: =AW36 -> 0 | AY36: =L36 -> 10.465
C37: TOTAL | D37: ='Economist OLD'!F38 | I37: =SUM(I22:I36) -> 48125.016 | J37: =SUM(J22:J36) -> 860578.95 | L37: =SUM(L22:L36) -> 1100.6009
C38: ='Economist OLD'!B38 -> EMEA 0 Tier 1 | D38: ='Economist OLD'!F39 -> C0Level + Custom audience targeting companies 5,000+ | E38: Audience | F38: ResponsiveBillboard | G38: Economist_EMEATier1_Audience_Display_ResponsiveBillboard | H38: Economist_EMEATier1_Audience | I38: ='Economist OLD'!S39+P38 -> 11519.336 | J38: ='Economist OLD'!M39 -> 231889.36 | K38: ='Economist OLD'!Q39 -> 49.676 | L38: ='Economist OLD'!AW39 -> 162.32255 | M38: ='Economist OLD'!AV39 -> 0.0007 | N38: 0.75 | O38: ='Economist OLD'!AS39 -> 279500 | P38: 0 | Q38: ='Economist OLD'!U39 -> 1128.232 | R38: ='Economist OLD'!V39 -> 1128.232 | S38: ='Economist OLD'!W39 -> 1128.232 | T38: ='Economist OLD'!X39 -> 1128.232 | U38: ='Economist OLD'!Y39 -> 1128.232 | V38: ='Economist OLD'!Z39 -> 1654.8895 | W38: ='Economist OLD'!AA39 -> 526.65745 | X38: ='Economist OLD'!AB39 -> 1128.232 | ... AA38: ='Economist OLD'!AE39 -> 940.36994 | AB38: 0 | AC38: ='Economist OLD'!AG39 -> 22711.813 | AD38: ='Economist OLD'!AH39 -> 22711.813 | AE38: ='Economist OLD'!AI39 -> 22711.813 | AF38: ='Economist OLD'!AJ39 -> 22711.813 | AG38: ='Economist OLD'!AK39 -> 22711.813 | AH38: ='Economist OLD'!AL39 -> 33313.662 | AI38: ='Economist OLD'!AM39 -> 10601.849 | AJ38: ='Economist OLD'!AN39 -> 22711.813 | ... AM38: ='Economist OLD'!AQ39 -> 18930.066 | AN38: 0 | AO38: =L38/11 -> 14.756595 | AP38: =AO38 -> 14.756595 | AQ38: =AP38 -> 14.756595 | AR38: =AQ38 -> 14.756595 | AS38: =AR38 -> 14.756595 | AT38: =AS38 -> 14.756595 | AU38: =AT38 -> 14.756595 | AV38: =AU38 -> 14.756595 | AW38: =AV38 -> 14.756595 | ... AY38: =AX38 -> 14.756595
D39: ='Economist OLD'!F40 -> C0Level + Custom audience targeting companies 5,000+ | E39: Audience | F39: ='Economist OLD'!I40 -> 300x600 | G39: Economist_EMEATier1_Audience_Display_300x600 | H39: Economist_EMEATier1_Audience | I39: ='Economist OLD'!S40+P39 -> 10194.668 | J39: ='Economist OLD'!M40 -> 240693.41 | K39: ='Economist OLD'!Q40 -> 41.92 | L39: ='Economist OLD'!AW40 -> 120.34671 | M39: ='Economist OLD'!AV40 -> 0.0005 | N39: 0.75 | O39: ='Economist OLD'!AS40 -> 279500 | P39: 104.8 | Q39: ='Economist OLD'!U40 -> 988.22641 | R39: ='Economist OLD'!V40 -> 988.22641 | S39: ='Economist OLD'!W40 -> 988.22641 | T39: ='Economist OLD'!X40 -> 988.22641 | U39: ='Economist OLD'!Y40 -> 988.22641 | V39: ='Economist OLD'!Z40 -> 1449.5294 | W39: ='Economist OLD'!AA40 -> 461.30299 | X39: ='Economist OLD'!AB40 -> 988.22641 | ... AA39: ='Economist OLD'!AE40 -> 823.6767 | AB39: 2500 | AC39: ='Economist OLD'!AG40 -> 23574.103 | AD39: ='Economist OLD'!AH40 -> 23574.103 | AE39: ='Economist OLD'!AI40 -> 23574.103 | AF39: ='Economist OLD'!AJ40 -> 23574.103 | AG39: ='Economist OLD'!AK40 -> 23574.103 | AH39: ='Economist OLD'!AL40 -> 34578.469 | AI39: ='Economist OLD'!AM40 -> 11004.365 | AJ39: ='Economist OLD'!AN40 -> 23574.103 | ... AM39: ='Economist OLD'!AQ40 -> 19648.776 | AN39: 1 | AO39: =L39/11 -> 10.94061 | AP39: =AO39 -> 10.94061 | AQ39: =AP39 -> 10.94061 | AR39: =AQ39 -> 10.94061 | AS39: =AR39 -> 10.94061 | AT39: =AS39 -> 10.94061 | AU39: =AT39 -> 10.94061 | AV39: =AU39 -> 10.94061 | AW39: =AV39 -> 10.94061 | ... AY39: =AX39 -> 10.94061
D40: ='Economist OLD'!F41 -> C0Level + Custom audience targeting companies 5,000+ | E40: Audience | F40: ='Economist OLD'!I41 -> Interscroller | G40: Economist_EMEATier1_Audience_Display_Interscroller | H40: Economist_EMEATier1_Audience | I40: ='Economist OLD'!S41+P40 -> 12285.997 | J40: ='Economist OLD'!M41 -> 293081.98 | K40: ='Economist OLD'!Q41 -> 41.92 | L40: ='Economist OLD'!AW41 -> 879.24593 | M40: ='Economist OLD'!AV41 -> 0.003 | N40: 0.75 | O40: ='Economist OLD'!AS41 -> 279500 | P40: 0 | Q40: ='Economist OLD'!U41 -> 1203.3206 | R40: ='Economist OLD'!V41 -> 1203.3206 | S40: ='Economist OLD'!W41 -> 1203.3206 | T40: ='Economist OLD'!X41 -> 1203.3206 | U40: ='Economist OLD'!Y41 -> 1203.3206 | V40: ='Economist OLD'!Z41 -> 1765.0294 | W40: ='Economist OLD'!AA41 -> 561.70874 | X40: ='Economist OLD'!AB41 -> 1203.3206 | ... AA40: ='Economist OLD'!AE41 -> 1002.9556 | AB40: 0 | AC40: ='Economist OLD'!AG41 -> 28705.168 | AD40: ='Economist OLD'!AH41 -> 28705.168 | AE40: ='Economist OLD'!AI41 -> 28705.168 | AF40: ='Economist OLD'!AJ41 -> 28705.168 | AG40: ='Economist OLD'!AK41 -> 28705.168 | AH40: ='Economist OLD'!AL41 -> 42104.709 | AI40: ='Economist OLD'!AM41 -> 13399.541 | AJ40: ='Economist OLD'!AN41 -> 28705.168 | ... AM40: ='Economist OLD'!AQ41 -> 23925.467 | AN40: 0 | AO40: =L40/11 -> 79.931448 | AP40: =AO40 -> 79.931448 | AQ40: =AP40 -> 79.931448 | AR40: =AQ40 -> 79.931448 | AS40: =AR40 -> 79.931448 | AT40: =AS40 -> 79.931448 | AU40: =AT40 -> 79.931448 | AV40: =AU40 -> 79.931448 | AW40: =AV40 -> 79.931448 | ... AY40: =AX40 -> 79.931448
D41: ='Economist OLD'!F42 -> C0Level + ESG articles and content | E41: Audience+Contextual | F41: ResponsiveBillboard | G41: Economist_EMEATier1_Audience+Contextual_Display_ResponsiveBillboard | H41: Economist_EMEATier1_Audience+Contextual | I41: ='Economist OLD'!S42+P41 -> 6033.3325 | J41: ='Economist OLD'!M42 -> 136039.06 | K41: ='Economist OLD'!Q42 -> 44.35 | L41: ='Economist OLD'!AW42 -> 95.227344 | M41: ='Economist OLD'!AV42 -> 0.0007 | N41: 0.75 | O41: ='Economist OLD'!AS42 -> 1060000 | P41: 0 | Q41: ='Economist OLD'!U42 -> 590.91939 | R41: ='Economist OLD'!V42 -> 590.91939 | S41: ='Economist OLD'!W42 -> 590.91939 | T41: ='Economist OLD'!X42 -> 590.91939 | U41: ='Economist OLD'!Y42 -> 590.91939 | V41: ='Economist OLD'!Z42 -> 866.7599 | W41: ='Economist OLD'!AA42 -> 275.84051 | X41: ='Economist OLD'!AB42 -> 590.91939 | ... AA41: ='Economist OLD'!AE42 -> 492.52532 | AB41: 0 | AC41: ='Economist OLD'!AG42 -> 13324 | AD41: ='Economist OLD'!AH42 -> 13324 | AE41: ='Economist OLD'!AI42 -> 13324 | AF41: ='Economist OLD'!AJ42 -> 13324 | AG41: ='Economist OLD'!AK42 -> 13324 | AH41: ='Economist OLD'!AL42 -> 19543.628 | AI41: ='Economist OLD'!AM42 -> 6219.6283 | AJ41: ='Economist OLD'!AN42 -> 13324 | ... AM41: ='Economist OLD'!AQ42 -> 11105.419 | AN41: 0 | AO41: =L41/11 -> 8.6570313 | AP41: =AO41 -> 8.6570313 | AQ41: =AP41 -> 8.6570313 | AR41: =AQ41 -> 8.6570313 | AS41: =AR41 -> 8.6570313 | AT41: =AS41 -> 8.6570313 | AU41: =AT41 -> 8.6570313 | AV41: =AU41 -> 8.6570313 | AW41: =AV41 -> 8.6570313 | ... AY41: =AX41 -> 8.6570313
D42: ='Economist OLD'!F43 -> C0Level + ESG articles and content | E42: Audience+Contextual | F42: ='Economist OLD'!I43 -> 300x600 | G42: Economist_EMEATier1_Audience+Contextual_Display_300x600 | H42: Economist_EMEATier1_Audience+Contextual | I42: ='Economist OLD'!S43+P42 -> 5383.5662 | J42: ='Economist OLD'!M43 -> 142046.6 | K42: ='Economist OLD'!Q43 -> 37.9 | L42: ='Economist OLD'!AW43 -> 71.023301 | M42: ='Economist OLD'!AV43 -> 0.0005 | N42: 0.75 | O42: ='Economist OLD'!AS43 -> 1060000 | P42: 0 | Q42: ='Economist OLD'!U43 -> 527.27969 | R42: ='Economist OLD'!V43 -> 527.27969 | S42: ='Economist OLD'!W43 -> 527.27969 | T42: ='Economist OLD'!X43 -> 527.27969 | U42: ='Economist OLD'!Y43 -> 527.27969 | V42: ='Economist OLD'!Z43 -> 773.41326 | W42: ='Economist OLD'!AA43 -> 246.13357 | X42: ='Economist OLD'!AB43 -> 527.27969 | ... AA42: ='Economist OLD'!AE43 -> 439.48228 | AB42: 0 | AC42: ='Economist OLD'!AG43 -> 13912.393 | AD42: ='Economist OLD'!AH43 -> 13912.393 | AE42: ='Economist OLD'!AI43 -> 13912.393 | AF42: ='Economist OLD'!AJ43 -> 13912.393 | AG42: ='Economist OLD'!AK43 -> 13912.393 | AH42: ='Economist OLD'!AL43 -> 20406.682 | AI42: ='Economist OLD'!AM43 -> 6494.2895 | AJ42: ='Economist OLD'!AN43 -> 13912.393 | ... AM42: ='Economist OLD'!AQ43 -> 11595.838 | AN42: 0 | AO42: =L42/11 -> 6.4566637 | AP42: =AO42 -> 6.4566637 | AQ42: =AP42 -> 6.4566637 | AR42: =AQ42 -> 6.4566637 | AS42: =AR42 -> 6.4566637 | AT42: =AS42 -> 6.4566637 | AU42: =AT42 -> 6.4566637 | AV42: =AU42 -> 6.4566637 | AW42: =AV42 -> 6.4566637 | ... AY42: =AX42 -> 6.4566637
D43: ='Economist OLD'!F44 -> C0Level + ESG articles and content | E43: Audience+Contextual | F43: ='Economist OLD'!I44 -> Interscroller | G43: Economist_EMEATier1_Audience+Contextual_Display_Interscroller | H43: Economist_EMEATier1_Audience+Contextual | I43: ='Economist OLD'!S44+P43 -> 6033.3325 | J43: ='Economist OLD'!M44 -> 159190.83 | K43: ='Economist OLD'!Q44 -> 37.9 | L43: ='Economist OLD'!AW44 -> 477.57249 | M43: ='Economist OLD'!AV44 -> 0.003 | N43: 0.75 | O43: ='Economist OLD'!AS44 -> 1060000 | P43: 0 | Q43: ='Economist OLD'!U44 -> 590.91939 | R43: ='Economist OLD'!V44 -> 590.91939 | S43: ='Economist OLD'!W44 -> 590.91939 | T43: ='Economist OLD'!X44 -> 590.91939 | U43: ='Economist OLD'!Y44 -> 590.91939 | V43: ='Economist OLD'!Z44 -> 866.7599 | W43: ='Economist OLD'!AA44 -> 275.84051 | X43: ='Economist OLD'!AB44 -> 590.91939 | ... AA43: ='Economist OLD'!AE44 -> 492.52532 | AB43: 0 | AC43: ='Economist OLD'!AG44 -> 15591.541 | AD43: ='Economist OLD'!AH44 -> 15591.541 | AE43: ='Economist OLD'!AI44 -> 15591.541 | AF43: ='Economist OLD'!AJ44 -> 15591.541 | AG43: ='Economist OLD'!AK44 -> 15591.541 | AH43: ='Economist OLD'!AL44 -> 22869.654 | AI43: ='Economist OLD'!AM44 -> 7278.1138 | AJ43: ='Economist OLD'!AN44 -> 15591.541 | ... AM43: ='Economist OLD'!AQ44 -> 12995.391 | AN43: 0 | AO43: =L43/11 -> 43.415681 | AP43: =AO43 -> 43.415681 | AQ43: =AP43 -> 43.415681 | AR43: =AQ43 -> 43.415681 | AS43: =AR43 -> 43.415681 | AT43: =AS43 -> 43.415681 | AU43: =AT43 -> 43.415681 | AV43: =AU43 -> 43.415681 | AW43: =AV43 -> 43.415681 | ... AY43: =AX43 -> 43.415681
...

Sheet Master_Plan_2025_Bigquery CB do
P4: SPEND | AB4: IMPRESSONS | AN4: CLICKS
B5: VENDOR | C5: REGION | D5: TARGETING | E5: TARGETING_TYPE | F5: PLACEMENT | G5: PLACEMENT_NAME | I5: SPEND | J5: IMPRESSIONS | K5: CPM | L5: CLICKS | M5: CTR | N5: VIEWABILITY | O5: Monthly_Unique_users | P5: FEBRUARY_spend | Q5: MARCH_spend | R5: APRIL_spend | S5: MAY_spend | T5: JUNE_spend | U5: JULY_spend | V5: AUGUST_spend | W5: SEPTEMBER_spend | X5: OCTOBER_spend | Y5: NOVEMBER_spend | Z5: DECEMBER_spend | AA5: JANUARY_spend | AB5: FEBRUARY_impressions | AC5: MARCH_impressions | AD5: APRIL_impressions | AE5: MAY_impressions | AF5: JUNE_impressions | AG5: JULY_impressions | AH5: AUGUST_impressions | AI5: SEPTEMBER_impressions | AJ5: OCTOBER_impressions | AK5: NOVEMBER_impressions | AL5: DECEMBER_impressions | AM5: JANUARY_impressions | AN5: FEBRUARY_clicks | AO5: MARCH_clicks | AP5: APRIL_clicks | AQ5: MAY_clicks | AR5: JUNE_clicks | AS5: JULY_clicks | AT5: AUGUST_clicks | AU5: SEPTEMBER_clicks | AV5: OCTOBER_clicks | AW5: NOVEMBER_clicks | AX5: DECEMBER_clicks | AY5: JANUARY_clicks
B6: THE ECONOMIST | C6: ='Economist OLD'!B6 -> North America 0 US (US Metro targetting, Canada Country targetting) | D6: ='Master Plan 2025'!D6 -> C0Level + Custom audience targeting companies 5,000+ | E6: ='Master Plan 2025'!E6 -> Audience | F6: ='Master Plan 2025'!F6 -> ResponsiveBillboard | G6: ='Master Plan 2025'!G6 -> Economist_US_Audience_Display_ResponsiveBillboard | I6: ='Master Plan 2025'!I6 -> 5799.38 | J6: ='Master Plan 2025'!J6 -> 116744.1 | K6: ='Master Plan 2025'!K6 -> 49.676 | L6: ='Master Plan 2025'!L6 -> 81.720871 | M6: ='Master Plan 2025'!M6 -> 0.0007 | N6: ='Master Plan 2025'!N6 -> 0.75 | O6: ='Master Plan 2025'!O6 -> 581400 | P6: ='Master Plan 2025'!P6 -> 0 | ... AY6: ='Master Plan 2025'!AY6 -> 7.4291701
D7: ='Master Plan 2025'!D7 -> C0Level + Custom audience targeting companies 5,000+ | E7: ='Master Plan 2025'!E7 -> Audience | F7: ='Master Plan 2025'!F7 -> 300x600 | G7: ='Master Plan 2025'!G7 -> Economist_US_Audience_Display_300x600 | I7: ='Master Plan 2025'!I7 -> 5682.4985 | J7: ='Master Plan 2025'!J7 -> 85263.085 | K7: ='Master Plan 2025'!K7 -> 41.92 | L7: ='Master Plan 2025'!L7 -> 42.631543 | M7: ='Master Plan 2025'!M7 -> 0.0005 | N7: ='Master Plan 2025'!N7 -> 0.75 | O7: ='Master Plan 2025'!O7 -> 581400 | P7: ='Master Plan 2025'!P7 -> 2108.27 | ... AY7: ='Master Plan 2025'!AY7 -> 3.8755948
D8: ='Master Plan 2025'!D8 -> C0Level + Custom audience targeting companies 5,000+ | E8: ='Master Plan 2025'!E8 -> Audience | F8: ='Master Plan 2025'!F8 -> Interscroller | G8: ='Master Plan 2025'!G8 -> Economist_US_Audience_Display_Interscroller | I8: ='Master Plan 2025'!I8 -> 5518.124 | J8: ='Master Plan 2025'!J8 -> 93833.589 | K8: ='Master Plan 2025'!K8 -> 41.92 | L8: ='Master Plan 2025'!L8 -> 281.50077 | M8: ='Master Plan 2025'!M8 -> 0.003 | N8: ='Master Plan 2025'!N8 -> 0.75 | O8: ='Master Plan 2025'!O8 -> 581400 | P8: ='Master Plan 2025'!P8 -> 1584.62 | ... AY8: ='Master Plan 2025'!AY8 -> 25.590979
D9: ='Master Plan 2025'!D9 -> C0Level + ESG articles and content | E9: ='Master Plan 2025'!E9 -> Audience+Contextual | F9: ='Master Plan 2025'!F9 -> ResponsiveBillboard | G9: ='Master Plan 2025'!G9 -> Economist_US_Audience+Contextual_Display_ResponsiveBillboard | I9: ='Master Plan 2025'!I9 -> 3656.25 | J9: ='Master Plan 2025'!J9 -> 82440.812 | K9: ='Master Plan 2025'!K9 -> 44.35 | L9: ='Master Plan 2025'!L9 -> 57.708568 | M9: ='Master Plan 2025'!M9 -> 0.0007 | N9: ='Master Plan 2025'!N9 -> 0.75 | O9: ='Master Plan 2025'!O9 -> 4175000 | P9: ='Master Plan 2025'!P9 -> 0 | ... AY9: ='Master Plan 2025'!AY9 -> 5.2462335
